WARNING:torch.distributed.run:
*****************************************
Setting OMP_NUM_THREADS environment variable for each process to be 1 in default, to avoid your system being overloaded, please further tune the variable for optimal performance in your application as needed. 
*****************************************
wandb: Currently logged in as: gengyuanzhang (use `wandb login --relogin` to force relogin)
/home/wiss/zhang/anaconda3/envs/probe-sl/lib/python3.7/site-packages/torch/functional.py:445: UserWarning: torch.meshgrid: in an upcoming release, it will be required to pass the indexing argument. (Triggered internally at  /opt/conda/conda-bld/pytorch_1639180594101/work/aten/src/ATen/native/TensorShape.cpp:2157.)
  return _VF.meshgrid(tensors, **kwargs)  # type: ignore[attr-defined]
wandb: ERROR Error communicating with wandb process
wandb: ERROR try: wandb.init(settings=wandb.Settings(start_method='fork'))
wandb: ERROR or:  wandb.init(settings=wandb.Settings(start_method='thread'))
wandb: ERROR For more info see: https://docs.wandb.ai/library/init#init-start-error
Traceback (most recent call last):
  File "tasks/vqa.py", line 295, in <module>
    main(cfg)
  File "tasks/vqa.py", line 169, in main
    run = setup_wandb(config)
  File "/home/wiss/zhang/Jinhe/singularity/utils/logger.py", line 35, in setup_wandb
    reinit=True
  File "/home/wiss/zhang/anaconda3/envs/probe-sl/lib/python3.7/site-packages/wandb/sdk/wandb_init.py", line 931, in init
    run = wi.init()
  File "/home/wiss/zhang/anaconda3/envs/probe-sl/lib/python3.7/site-packages/wandb/sdk/wandb_init.py", line 598, in init
    raise UsageError(error_message)
wandb.errors.UsageError: Error communicating with wandb process
try: wandb.init(settings=wandb.Settings(start_method='fork'))
or:  wandb.init(settings=wandb.Settings(start_method='thread'))
For more info see: https://docs.wandb.ai/library/init#init-start-error
WARNING:torch.distributed.elastic.multiprocessing.api:Sending process 252086 closing signal SIGTERM
ERROR:torch.distributed.elastic.multiprocessing.api:failed (exitcode: 1) local_rank: 0 (pid: 252077) of binary: /home/wiss/zhang/anaconda3/envs/probe-sl/bin/python
Traceback (most recent call last):
  File "/home/wiss/zhang/anaconda3/envs/probe-sl/bin/torchrun", line 33, in <module>
    sys.exit(load_entry_point('torch==1.10.1', 'console_scripts', 'torchrun')())
  File "/home/wiss/zhang/anaconda3/envs/probe-sl/lib/python3.7/site-packages/torch/distributed/elastic/multiprocessing/errors/__init__.py", line 345, in wrapper
    return f(*args, **kwargs)
  File "/home/wiss/zhang/anaconda3/envs/probe-sl/lib/python3.7/site-packages/torch/distributed/run.py", line 719, in main
    run(args)
  File "/home/wiss/zhang/anaconda3/envs/probe-sl/lib/python3.7/site-packages/torch/distributed/run.py", line 713, in run
    )(*cmd_args)
  File "/home/wiss/zhang/anaconda3/envs/probe-sl/lib/python3.7/site-packages/torch/distributed/launcher/api.py", line 131, in __call__
    return launch_agent(self._config, self._entrypoint, list(args))
  File "/home/wiss/zhang/anaconda3/envs/probe-sl/lib/python3.7/site-packages/torch/distributed/launcher/api.py", line 261, in launch_agent
    failures=result.failures,
torch.distributed.elastic.multiprocessing.errors.ChildFailedError: 
============================================================
tasks/vqa.py FAILED
------------------------------------------------------------
Failures:
  <NO_OTHER_FAILURES>
------------------------------------------------------------
Root Cause (first observed failure):
[0]:
  time      : 2023-10-18_02:28:22
  host      : worker-6
  rank      : 0 (local_rank: 0)
  exitcode  : 1 (pid: 252077)
  error_file: <N/A>
  traceback : To enable traceback see: https://pytorch.org/docs/stable/elastic/errors.html
============================================================
